<?xml version="1.0" ?>
<robot name="kamuy2" xmlns:xacro="http://www.ros.org/wiki/xacro">

<xacro:include filename="$(find kamuy2_description)/urdf/materials.xacro" />
<xacro:include filename="$(find kamuy2_description)/urdf/kamuy2.trans" />
<xacro:include filename="$(find kamuy2_description)/urdf/kamuy2.gazebo" />
<link name="base_link">
  <inertial>
    <origin xyz="0 -0.01 0.03" rpy="0 0 0"/>
    <mass value="5"/>
    <inertia ixx="0.0666" iyy="0.24166" izz="0.24166" ixy="0.0" iyz="0" ixz="0"/>
  </inertial>
  <visual>
    <origin xyz="0 -0.01 0.03" rpy="0 0 0"/>
    <geometry>
      <mesh filename="package://kamuy2_description/meshes/base_link.stl" scale="0.001 0.001 0.001"/>
    </geometry>
    <material name="silver"/>
  </visual>
  <collision>
    <origin xyz="0 -0.01 0.03" rpy="0 0 0"/>
    <geometry>
      <mesh filename="package://kamuy2_description/meshes/base_link.stl" scale="0.001 0.001 0.001"/>
    </geometry>
                          <surface>
                    <friction>
                        <ode>
                            <mu>10</mu>
                            <mu2>10</mu2>
                        </ode>
                    </friction>
                </surface>
  </collision>
</link>

<!-- sensor -->
<link name="camera_link">

  <visual>
    <origin xyz="0 0.0 0" rpy="0 0 0"/>
    <geometry>
      <sphere radius="0.05"/>
    </geometry>
    <material name="silver"/>
  </visual>
</link>

<link name="imu_link">

  <visual>
    <origin xyz="0 0.0 0" rpy="0 0 0"/>
    <geometry>
      <sphere radius="0.05"/>
    </geometry>
    <material name="silver"/>
  </visual>
</link>

<link name="lidar_link">

  <visual>
    <origin xyz="0 0.0 0" rpy="0 0 0"/>
    <geometry>
      <sphere radius="0.05"/>
    </geometry>
    <material name="silver"/>
  </visual>
</link>

<!-- second link -->
<link name="front_left_link_second">
  <inertial>
    <origin xyz="0 0 0" rpy="0 1.570796 0"/>
    <mass value="0.5"/>
    <inertia ixx="0.00712" iyy="0.007101" izz="0.000185416" ixy="0.0" iyz="0" ixz="0"/>
  </inertial>
  <visual>
    <origin xyz="0 0 0" rpy="0 1.570796 0"/>
    <geometry>
      <mesh filename="package://kamuy2_description/meshes/front_left_link_second.stl" scale="0.001 0.001 0.001"/>
    </geometry>
    <material name="silver"/>
  </visual>
  <collision>
    <origin xyz="0 0 0" rpy="0 1.570796 0"/>
    <geometry>
      <mesh filename="package://kamuy2_description/meshes/front_left_link_second.stl" scale="0.001 0.001 0.001"/>
    </geometry>
                          <surface>
                    <friction>
                        <ode>
                            <mu>10</mu>
                            <mu2>10</mu2>
                        </ode>
                    </friction>
                </surface>
  </collision>
</link>

<link name="back_left_link_second">
  <inertial>
    <origin xyz="0 0 0" rpy="0 1.570796 0"/>
    <mass value="0.5"/>
    <inertia ixx="0.00712" iyy="0.007101" izz="0.000185416" ixy="0.0" iyz="0" ixz="0"/>
  </inertial>
  <visual>
    <origin xyz="0 0 0" rpy="0 1.570796 0"/>
    <geometry>
      <mesh filename="package://kamuy2_description/meshes/back_left_link_second.stl" scale="0.001 0.001 0.001"/>
    </geometry>
    <material name="silver"/>
  </visual>
  <collision>
    <origin xyz="0 0 0" rpy="0 1.570796 0"/>
    <geometry>
      <mesh filename="package://kamuy2_description/meshes/back_left_link_second.stl" scale="0.001 0.001 0.001"/>
    </geometry>
                          <surface>
                    <friction>
                        <ode>
                            <mu>10</mu>
                            <mu2>10</mu2>
                        </ode>
                    </friction>
                </surface>
  </collision>
</link>

<link name="front_right_link_second">
  <inertial>
    <origin xyz="0 0 0" rpy="0 1.570796 0"/>
    <mass value="0.5"/>
    <inertia ixx="0.00712" iyy="0.007101" izz="0.000185416" ixy="0.0" iyz="0" ixz="0"/>
  </inertial>
  <visual>
    <origin xyz="0 0 0" rpy="0 1.570796 0"/>
    <geometry>
      <mesh filename="package://kamuy2_description/meshes/front_right_link_second.stl" scale="0.001 0.001 0.001"/>
    </geometry>
    <material name="silver"/>
  </visual>
  <collision>
    <origin xyz="0 0 0" rpy="0 1.570796 0"/>
    <geometry>
      <mesh filename="package://kamuy2_description/meshes/front_right_link_second.stl" scale="0.001 0.001 0.001"/>
    </geometry>
                          <surface>
                    <friction>
                        <ode>
                            <mu>10</mu>
                            <mu2>10</mu2>
                        </ode>
                    </friction>
                </surface>
  </collision>
</link>

<link name="back_right_link_second">
  <inertial>
    <origin xyz="0 0 0" rpy="0 1.570796 0"/>
    <mass value="0.5"/>
    <inertia ixx="0.00712" iyy="0.007101" izz="0.000185416" ixy="0.0" iyz="0" ixz="0"/>
  </inertial>
  <visual>
    <origin xyz="0 0 0" rpy="0 1.570796 0"/>
    <geometry>
      <mesh filename="package://kamuy2_description/meshes/back_right_link_second.stl" scale="0.001 0.001 0.001"/>
    </geometry>
    <material name="silver"/>
  </visual>
  <collision>
    <origin xyz="0 0 0" rpy="0 1.570796 0"/>
    <geometry>
      <mesh filename="package://kamuy2_description/meshes/back_right_link_second.stl" scale="0.001 0.001 0.001"/>
    </geometry>
                          <surface>
                    <friction>
                        <ode>
                            <mu>10</mu>
                            <mu2>10</mu2>
                        </ode>
                    </friction>
                </surface>
  </collision>
</link>

<!-- first link -->
<link name="front_right_link_first">
  <inertial>
    <origin xyz="0 0 0" rpy="0 0 0"/>
    <mass value="1.4"/>
    <inertia ixx="0.001666" iyy="0.005413" izz="0.0050866" ixy="0" iyz="0" ixz="0"/>
  </inertial>
  <visual>
    <origin xyz="0 0 0" rpy="0 0 3.141592"/>
    <geometry>
      <mesh filename="package://kamuy2_description/meshes/front_right_link_first.stl" scale="0.001 0.001 0.001"/>
    </geometry>
    <material name="silver"/>
  </visual>
  <collision>
    <origin xyz="0 0 0" rpy="0 0 3.141592"/>
    <geometry>
      <mesh filename="package://kamuy2_description/meshes/front_right_link_first.stl" scale="0.001 0.001 0.001"/>
    </geometry>
                          <surface>
                    <friction>
                        <ode>
                            <mu>10</mu>
                            <mu2>10</mu2>
                        </ode>
                    </friction>
                </surface>
  </collision>
</link>

<link name="front_left_link_first">
  <inertial>
    <origin xyz="0 0 0" rpy="0 0 0"/>
    <mass value="1.4"/>
    <inertia ixx="0.001666" iyy="0.005413" izz="0.0050866" ixy="0" iyz="0" ixz="0"/>
  </inertial>
  <visual>
    <origin xyz="0 0 0" rpy="0 0 3.141592"/>
    <geometry>
      <mesh filename="package://kamuy2_description/meshes/front_left_link_first.stl" scale="0.001 0.001 0.001"/>
    </geometry>
    <material name="silver"/>
  </visual>
  <collision>
    <origin xyz="0 0 0" rpy="0 0 3.141592"/>
    <geometry>
      <mesh filename="package://kamuy2_description/meshes/front_left_link_first.stl" scale="0.001 0.001 0.001"/>
    </geometry>
                          <surface>
                    <friction>
                        <ode>
                            <mu>10</mu>
                            <mu2>10</mu2>
                        </ode>
                    </friction>
                </surface>
  </collision>
</link>

<link name="back_right_link_first">
  <inertial>
    <origin xyz="0 0 0" rpy="0 0 0"/>
    <mass value="1.4"/>
    <inertia ixx="0.001666" iyy="0.005413" izz="0.0050866" ixy="0" iyz="0" ixz="0"/>
  </inertial>
  <visual>
    <origin xyz="0 0 0" rpy="0 0 0"/>
    <geometry>
      <mesh filename="package://kamuy2_description/meshes/back_right_link_first.stl" scale="0.001 0.001 0.001"/>
    </geometry>
    <material name="silver"/>
  </visual>
  <collision>
    <origin xyz="0 0 0" rpy="0 0 0"/>
    <geometry>
      <mesh filename="package://kamuy2_description/meshes/back_right_link_first.stl" scale="0.001 0.001 0.001"/>
    </geometry>
                          <surface>
                    <friction>
                        <ode>
                            <mu>10</mu>
                            <mu2>10</mu2>
                        </ode>
                    </friction>
                </surface>
  </collision>
</link>

<link name="back_left_link_first">
  <inertial>
    <origin xyz="0.0944653660519865 0.003464242618647702 -0.03287189320851288" rpy="0 0 0"/>
    <mass value="1.4"/>
    <inertia ixx="0.001666" iyy="0.005413" izz="0.0050866" ixy="0" iyz="0" ixz="0"/>
  </inertial>
  <visual>
    <origin xyz="0 0 0" rpy="0 0 0"/>
    <geometry>
      <mesh filename="package://kamuy2_description/meshes/back_left_link_first.stl" scale="0.001 0.001 0.001"/>
    </geometry>
    <material name="silver"/>
  </visual>
  <collision>
    <origin xyz="0 0 0" rpy="0 0 0"/>
    <geometry>
      <mesh filename="package://kamuy2_description/meshes/back_left_link_first.stl" scale="0.001 0.001 0.001"/>
    </geometry>
                          <surface>
                    <friction>
                        <ode>
                            <mu>10</mu>
                            <mu2>10</mu2>
                        </ode>
                    </friction>
                </surface>
  </collision>
</link>

<!-- foot -->
<link name="back_left_link_foot">
  <inertial>
    <origin xyz="0 0 0" rpy="0 1.570796 0"/>
    <mass value="0.5"/>
    <inertia ixx="0.00770833" iyy="0.00895833" izz="0.003333" ixy="0" iyz="0" ixz="-0.0025"/>
  </inertial>
  <visual>
    <origin xyz="0 0 0" rpy="0 1.570796 0"/>
    <geometry>
      <mesh filename="package://kamuy2_description/meshes/back_left_link_foot.stl" scale="0.001 0.001 0.001"/>
    </geometry>
    <material name="silver"/>
  </visual>
  <collision>
    <origin xyz="0 0 0" rpy="0 1.570796 0"/>
    <geometry>
      <mesh filename="package://kamuy2_description/meshes/back_left_link_foot.stl" scale="0.001 0.001 0.001"/>
    </geometry>
                    <surface>
                    <friction>
                        <ode>
                            <mu>10</mu>
                            <mu2>10</mu2>
                        </ode>
                    </friction>
                </surface>
  </collision>

</link>

<link name="front_left_link_foot">
  <inertial>
    <origin xyz="0 0 0" rpy="0 1.570796 0"/>
    <mass value="0.5"/>
   <inertia ixx="0.00770833" iyy="0.00895833" izz="0.003333" ixy="0" iyz="0" ixz="-0.0025"/>
  </inertial>
  <visual>
    <origin xyz="0 0 0" rpy="0 1.570796 0"/>
    <geometry>
      <mesh filename="package://kamuy2_description/meshes/front_left_link_foot.stl" scale="0.001 0.001 0.001"/>
    </geometry>
    <material name="silver"/>
  </visual>
  <collision>
    <origin xyz="0 0 0" rpy="0 1.570796 0"/>
    <geometry>
      <mesh filename="package://kamuy2_description/meshes/front_left_link_foot.stl" scale="0.001 0.001 0.001"/>
    </geometry>
                    <surface>
                    <friction>
                        <ode>
                            <mu>10</mu>
                            <mu2>10</mu2>
                        </ode>
                    </friction>
                </surface>
  </collision>

</link>

<link name="front_right_link_foot">
  <inertial>
    <origin xyz="0 0 0" rpy="3.141592 1.570796 0"/>
    <mass value="0.5"/>
    <inertia ixx="0.00770833" iyy="0.00895833" izz="0.003333" ixy="0" iyz="0" ixz="-0.0025"/>
  </inertial>
  <visual>
    <origin xyz="0 0 0" rpy="3.141592 1.570796 0"/>
    <geometry>
      <mesh filename="package://kamuy2_description/meshes/front_right_link_foot.stl" scale="0.001 0.001 0.001"/>
    </geometry>
    <material name="silver"/>
  </visual>
  <collision>
    <origin xyz="0 0 0" rpy="3.141592 1.570796 0"/>
    <geometry>
      <mesh filename="package://kamuy2_description/meshes/front_right_link_foot.stl" scale="0.001 0.001 0.001"/>
    </geometry>
                    <surface>
                    <friction>
                        <ode>
                            <mu>10</mu>
                            <mu2>10</mu2>
                        </ode>
                    </friction>
                </surface>
 </collision>
</link>

<link name="back_right_link_foot">
  <inertial>
    <origin xyz="0 0 0" rpy="3.141592 1.570796 0"/>
    <mass value="0.5"/>
   <inertia ixx="0.00770833" iyy="0.00895833" izz="0.003333" ixy="0" iyz="0" ixz="-0.0025"/>
  </inertial>
  <visual>
    <origin xyz="0 0 0" rpy="3.141592 1.570796 0"/>
    <geometry>
      <mesh filename="package://kamuy2_description/meshes/back_right_link_foot.stl" scale="0.001 0.001 0.001"/>
    </geometry>
    <material name="silver"/>
  </visual>
  <collision>
    <origin xyz="0 0 0" rpy="3.141592 1.570796 0"/>
    <geometry>
      <mesh filename="package://kamuy2_description/meshes/back_right_link_foot.stl" scale="0.001 0.001 0.001"/>
    </geometry>
                    <surface>
                    <friction>
                        <ode>
                            <mu>10</mu>
                            <mu2>10</mu2>
                        </ode>
                    </friction>
                </surface>
  </collision>

</link>

<link name="front_left_foot">
  <inertial>
    <origin xyz="0 0 0" rpy="0 0 0"/>
    <mass value="0.1"/>
    <inertia ixx="0.1" iyy="0.1" izz="0.1" ixy="0" iyz="0" ixz="0"/>
  </inertial>
    <visual>
      <geometry>
          <sphere radius="0.04"/>
      </geometry>
    </visual>
    <collision>
      <geometry>
          <sphere radius="0.04"/>
      </geometry>
                <surface>
                    <friction>
                        <ode>
                            <mu>10</mu>
                            <mu2>10</mu2>
                        </ode>
                    </friction>
                </surface>
    </collision>


</link>

<link name="front_right_foot">
  <inertial>
    <origin xyz="0 0 0" rpy="0 0 0"/>
    <mass value="0.1"/>
    <inertia ixx="0.1" iyy="0.1" izz="0.1" ixy="0" iyz="0" ixz="0"/>
  </inertial>
    <visual>
      <geometry>
          <sphere radius="0.04"/>
      </geometry>
  
    </visual>
    <collision>
      <geometry>
          <sphere radius="0.04"/>
      </geometry>
                      <surface>
                    <friction>
                        <ode>
                            <mu>10</mu>
                            <mu2>10</mu2>
                        </ode>
                    </friction>
                </surface>
    </collision>


</link>

<link name="back_left_foot">
  <inertial>
    <origin xyz="0 0 0" rpy="0 0 0"/>
    <mass value="0.1"/>
    <inertia ixx="0.1" iyy="0.1" izz="0.1" ixy="0" iyz="0" ixz="0"/>
  </inertial>
    <visual>
      <geometry>
          <sphere radius="0.04"/>
      </geometry>
     
    </visual>
    <collision>
      <geometry>
          <sphere radius="0.04"/>
      </geometry>
                      <surface>
                    <friction>
                        <ode>
                            <mu>10</mu>
                            <mu2>10</mu2>
                        </ode>
                    </friction>
                </surface>
    </collision>


</link>

<link name="back_right_foot">
  <inertial>
    <origin xyz="0 0 0" rpy="0 0 0"/>
    <mass value="0.1"/>
    <inertia ixx="0.1" iyy="0.1" izz="0.1" ixy="0" iyz="0" ixz="0"/>
  </inertial>
    <visual>
      <geometry>
          <sphere radius="0.04"/>
      </geometry>
     
    </visual>
    <collision>
      <geometry>
          <sphere radius="0.04"/>
      </geometry>
                      <surface>
                    <friction>
                        <ode>
                            <mu>10</mu>
                            <mu2>10</mu2>
                        </ode>
                    </friction>
                </surface>
    </collision>


</link>


<!--


<joint name="fr1" type="revolute">
  <origin xyz="0.295288 -0.072993 0.06454" rpy="0 0 0"/>
  <parent link="base_link"/>
  <child link="front_right_link_first"/>
  <axis xyz="-1.0 0.0 0.0"/>
  <limit upper="0.785398" lower="-0.785398" effort="20" velocity="1.5"/>
</joint>

<joint name="fl1" type="revolute">
  <origin xyz="0.295288 0.057189 0.06454" rpy="0 0 0"/>
  <parent link="base_link"/>
  <child link="front_left_link_first"/>
  <axis xyz="-1.0 0.0 0.0"/>
  <limit upper="0.785398" lower="-0.785398" effort="20" velocity="1.5"/>
</joint>

<joint name="br1" type="revolute">
  <origin xyz="-0.287095 -0.06509 0.031" rpy="0 0 0"/>
  <parent link="base_link"/>
  <child link="back_right_link_first"/>
  <axis xyz="-1.0 0 -0.0"/>
  <limit upper="0.785398" lower="-0.785398" effort="20" velocity="1.5"/>
</joint>

<joint name="bl1" type="revolute">
  <origin xyz="-0.279337 0.057192 0.06454" rpy="0 0 0"/>
  <parent link="base_link"/>
  <child link="back_left_link_first"/>
  <axis xyz="-1.0 0 -0.0"/>
  <limit upper="0.785398" lower="-0.785398" effort="20" velocity="1.5"/>
</joint>

<joint name="fl2" type="revolute">
  <origin xyz="-0.094399 0.094475 -0.033545" rpy="0 0 0"/>
  <parent link="front_left_link_first"/>
  <child link="front_left_link_second"/>
  <axis xyz="0.0 1.0 0.0"/>
  <limit upper="3.141593" lower="0.0" effort="20" velocity="1.5"/>
</joint>

<joint name="bl2" type="revolute">
  <origin xyz="0.078886 0.094475 -0.033545" rpy="0 0 0"/>
  <parent link="back_left_link_first"/>
  <child link="back_left_link_second"/>
  <axis xyz="-0 -1.0 -0.0"/>
  <limit upper="0.087266" lower="-3.141593" effort="20" velocity="1.5"/>
</joint>

<joint name="fr2" type="revolute">
  <origin xyz="-0.094399 -0.078675 -0.033545" rpy="0 0 0"/>
  <parent link="front_right_link_first"/>
  <child link="front_right_link_second"/>
  <axis xyz="-0.0 1.0 -0.0"/>
  <limit upper="3.141593" lower="0.0" effort="20" velocity="1.5"/>
</joint>

<joint name="br2" type="revolute">
  <origin xyz="0.084642 -0.086575 -0" rpy="0 0 0"/>
  <parent link="back_right_link_first"/>
  <child link="back_right_link_second"/>
  <axis xyz="-0 -1.0 -0.0"/>
  <limit upper="0.0" lower="-3.141593" effort="20" velocity="1.5"/>
</joint>



<joint name="bl3" type="revolute">
  <origin xyz="-0.169004 0.127167 0.200451" rpy="0 0 0"/>
  <parent link="back_left_link_second"/>
  <child link="back_left_link_foot"/>
  <axis xyz="-0 -1.0 -0.0"/>
  <limit upper="3.141593" lower="0.0" effort="20" velocity="1.5"/>
</joint>

<joint name="fl3" type="revolute">
  <origin xyz="-0.169005 0.130164 -0.200889" rpy="0 0 0"/>
  <parent link="front_left_link_second"/>
  <child link="front_left_link_foot"/>
  <axis xyz="-0.0 -1.0 -0.0"/>
  <limit upper="3.141593" lower="0.0" effort="20" velocity="1.5"/>
</joint>

<joint name="fr3" type="revolute">
  <origin xyz="-0.169005 -0.127168 -0.200889" rpy="0 0 0"/>
  <parent link="front_right_link_second"/>
  <child link="front_right_link_foot"/>
  <axis xyz="0.0 -1.0 0.0"/>
  <limit upper="3.141593" lower="0.0" effort="20" velocity="1.5"/>
</joint>

<joint name="br3" type="revolute">
  <origin xyz="-0.169005 -0.127165 0.202453" rpy="0 0 0"/>
  <parent link="back_right_link_second"/>
  <child link="back_right_link_foot"/>
  <axis xyz="-0 -1.0 -0.0"/>
  <limit upper="3.141593" lower="0.0" effort="20" velocity="1.5"/>
</joint>

-->

<joint name="fr1" type="revolute">
  <origin xyz="0.200441 -0.065042 0.030961" rpy="0 0 0"/>
  <parent link="base_link"/>
  <child link="front_right_link_first"/>
  <axis xyz="1.0 0.0 0.0"/>
  <limit upper="0.785398" lower="-0.785398" effort="20" velocity="1.5"/>
</joint>

<joint name="fl1" type="revolute">
  <origin xyz="0.200441 0.065042 0.030961" rpy="0 0 0"/>
  <parent link="base_link"/>
  <child link="front_left_link_first"/>
  <axis xyz="1.0 0.0 0.0"/>
  <limit upper="0.785398" lower="-0.785398" effort="20" velocity="1.5"/>
</joint>

<joint name="br1" type="revolute">
  <origin xyz="-0.200441 -0.06509 0.030961" rpy="0 0 0"/>
  <parent link="base_link"/>
  <child link="back_right_link_first"/>
  <axis xyz="1.0 0 -0.0"/>
  <limit upper="0.785398" lower="-0.785398" effort="20" velocity="1.5"/>
</joint>

<joint name="bl1" type="revolute">
  <origin xyz="-0.200441 0.065042 0.030961" rpy="0 0 0"/>
  <parent link="base_link"/>
  <child link="back_left_link_first"/>
  <axis xyz="1.0 0 -0.0"/>
  <limit upper="0.785398" lower="-0.785398" effort="20" velocity="1.5"/>
</joint>

<joint name="fl2" type="revolute">
  <origin xyz="0 0.094475 0" rpy="0 0 0"/>
  <parent link="front_left_link_first"/>
  <child link="front_left_link_second"/>
  <axis xyz="0.0 1.0 0.0"/>
  <limit upper="3.141593" lower="0.0" effort="20" velocity="1.5"/>
</joint>

<joint name="bl2" type="revolute">
  <origin xyz="0 0.094475 0" rpy="0 0 0"/>
  <parent link="back_left_link_first"/>
  <child link="back_left_link_second"/>
  <axis xyz="0.0 1.0 0.0"/>
  <limit upper="3.141593" lower="0.0" effort="20" velocity="1.5"/>
</joint>

<joint name="fr2" type="revolute">
  <origin xyz="0 -0.078675 0" rpy="0 0 0"/>
  <parent link="front_right_link_first"/>
  <child link="front_right_link_second"/>
  <axis xyz="-0.0 1.0 -0.0"/>
  <limit upper="3.141593" lower="0.0" effort="20" velocity="1.5"/>
</joint>

<joint name="br2" type="revolute">
  <origin xyz="0 -0.086575 0" rpy="0 0 0"/>
  <parent link="back_right_link_first"/>
  <child link="back_right_link_second"/>
  <axis xyz="-0.0 1.0 -0.0"/>
  <limit upper="3.141593" lower="0.0" effort="20" velocity="1.5"/>
</joint>



<joint name="bl3" type="revolute">
  <origin xyz=" 0 0 -0.200" rpy="0 0 0"/>
  <parent link="back_left_link_second"/>
  <child link="back_left_link_foot"/>
  <axis xyz="0 1 -0.0"/>
  <limit upper="0" lower="-3.141592" effort="20" velocity="1.5"/>
</joint>

<joint name="fl3" type="revolute">
  <origin xyz="0 0 -0.200 " rpy="0 0 0"/>
  <parent link="front_left_link_second"/>
  <child link="front_left_link_foot"/>
  <axis xyz="-0.0 1.0 -0.0"/>
  <limit upper="0" lower="-3.141592" effort="20" velocity="1.5"/>
</joint>

<joint name="fr3" type="revolute">
  <origin xyz="0 0 -0.200 " rpy="0 0 0"/>
  <parent link="front_right_link_second"/>
  <child link="front_right_link_foot"/>
  <axis xyz="0.0 1.0 0.0"/>
  <limit upper="0" lower="-3.141592" effort="20" velocity="1.5"/>
</joint>

<joint name="br3" type="revolute">
  <origin xyz="0 0 -0.200 " rpy="0 0 0"/>
  <parent link="back_right_link_second"/>
  <child link="back_right_link_foot"/>
  <axis xyz="0 1.0 -0.0"/>
  <limit upper="0" lower="-3.141592" effort="20" velocity="1.5"/>
</joint>


<joint name="fl4" type="fixed">
  <origin xyz="-0.05 0 -0.22" rpy="0 0 0"/>
  <parent link="front_left_link_foot"/>
  <child link="front_left_foot"/>
  <axis xyz="0.0 1.0 -0.0"/>
  <limit upper="3.141593" lower="0.0" effort="20" velocity="1.5"/>
</joint>

<joint name="fr4" type="fixed">
 <origin xyz="-0.05 0 -0.22 " rpy="0 0 0"/>
  <parent link="front_right_link_foot"/>
  <child link="front_right_foot"/>
  <axis xyz="0.0 1.0 -0.0"/>
  <limit upper="3.141593" lower="0.0" effort="20" velocity="1.5"/>
</joint>

<joint name="bl4" type="fixed">
  <origin xyz="-0.05 0 -0.22" rpy="0 0 0"/>
  <parent link="back_left_link_foot"/>
  <child link="back_left_foot"/>
  <axis xyz="0.0 1.0 -0.0"/>
  <limit upper="3.141593" lower="0.0" effort="20" velocity="1.5"/>
</joint>

<joint name="br4" type="fixed">
 <origin xyz="-0.05 0 -0.22" rpy="0 0 0"/>
  <parent link="back_right_link_foot"/>
  <child link="back_right_foot"/>
  <axis xyz="-0.0 -1.0 -0.0"/>
  <limit upper="3.141593" lower="0.0" effort="20" velocity="1.5"/>
</joint>

<joint name="camera_joint" type="fixed">
 <origin xyz="0.3 0 0" rpy="0 0 0"/>
  <parent link="base_link"/>
  <child link="camera_link"/>
  <axis xyz="0 0 0"/>
</joint>

<joint name="imu_joint" type="fixed">
 <origin xyz="0 0 0" rpy="0 0 0"/>
  <parent link="base_link"/>
  <child link="imu_link"/>
  <axis xyz="0 0 0"/>
</joint>
<gazebo>
    <plugin filename="libhector_gazebo_ros_imu.so" name="imu_controller">
      <updateRate>50.0</updateRate>
      <bodyName>imu_link</bodyName>
      <topicName>imu/data</topicName>
      <accelDrift>0.005 0.005 0.005</accelDrift>
      <accelGaussianNoise>0.005 0.005 0.005</accelGaussianNoise>
      <rateDrift>0.005 0.005 0.005 </rateDrift>
      <rateGaussianNoise>0.005 0.005 0.005 </rateGaussianNoise>
      <headingDrift>0.005</headingDrift>
      <headingGaussianNoise>0.005</headingGaussianNoise>
    </plugin>
  </gazebo>

<joint name="lidar_joint" type="fixed">
 <origin xyz="0 0 0" rpy="0 0 0"/>
  <parent link="base_link"/>
  <child link="lidar_link"/>
  <axis xyz="0 0 0.3"/>
</joint>
<!-- 
<transmission name="fr1_trans">
  <type>transmission_interface/SimpleTransmission</type>
  <joint name="fr1">
    <hardwareInterface>hardware_interface/EffortJointInterface</hardwareInterface>
  </joint>
  <actuator name="fr1_motor">
     <hardwareInterface>hardware_interface/EffortJointInterface</hardwareInterface>
      <mechanismReduction>1</mechanismReduction>
  </actuator>
</transmission>

<transmission name="fl1_trans">
  <type>transmission_interface/SimpleTransmission</type>
  <joint name="fl1">
    <hardwareInterface>hardware_interface/EffortJointInterface</hardwareInterface>
  </joint>
  <actuator name="fl1_motor">
     <hardwareInterface>hardware_interface/EffortJointInterface</hardwareInterface>
      <mechanismReduction>1</mechanismReduction>
  </actuator>
</transmission>

<transmission name="br1_trans">
  <type>transmission_interface/SimpleTransmission</type>
  <joint name="br1">
    <hardwareInterface>hardware_interface/EffortJointInterface</hardwareInterface>
  </joint>
  <actuator name="br1_motor">
     <hardwareInterface>hardware_interface/EffortJointInterface</hardwareInterface>
      <mechanismReduction>1</mechanismReduction>
  </actuator>
</transmission>

<transmission name="bl1_trans">
  <type>transmission_interface/SimpleTransmission</type>
  <joint name="bl1">
    <hardwareInterface>hardware_interface/EffortJointInterface</hardwareInterface>
  </joint>
  <actuator name="bl1_motor">
     <hardwareInterface>hardware_interface/EffortJointInterface</hardwareInterface>
      <mechanismReduction>1</mechanismReduction>
  </actuator>
</transmission>

<transmission name="fr2_trans">
  <type>transmission_interface/SimpleTransmission</type>
  <joint name="fr2">
    <hardwareInterface>hardware_interface/EffortJointInterface</hardwareInterface>
  </joint>
  <actuator name="fr2_motor">
     <hardwareInterface>hardware_interface/EffortJointInterface</hardwareInterface>
      <mechanismReduction>1</mechanismReduction>
  </actuator>
</transmission>

<transmission name="fl2_trans">
  <type>transmission_interface/SimpleTransmission</type>
  <joint name="fl2">
    <hardwareInterface>hardware_interface/EffortJointInterface</hardwareInterface>
  </joint>
  <actuator name="fl2_motor">
     <hardwareInterface>hardware_interface/EffortJointInterface</hardwareInterface>
      <mechanismReduction>1</mechanismReduction>
  </actuator>
</transmission>

<transmission name="br2_trans">
  <type>transmission_interface/SimpleTransmission</type>
  <joint name="br2">
    <hardwareInterface>hardware_interface/EffortJointInterface</hardwareInterface>
  </joint>
  <actuator name="br2_motor">
     <hardwareInterface>hardware_interface/EffortJointInterface</hardwareInterface>
      <mechanismReduction>1</mechanismReduction>
  </actuator>
</transmission>

<transmission name="bl2_trans">
  <type>transmission_interface/SimpleTransmission</type>
  <joint name="bl2">
    <hardwareInterface>hardware_interface/EffortJointInterface</hardwareInterface>
  </joint>
  <actuator name="bl2_motor">
     <hardwareInterface>hardware_interface/EffortJointInterface</hardwareInterface>
      <mechanismReduction>1</mechanismReduction>
  </actuator>
</transmission>

<transmission name="fr3_trans">
  <type>transmission_interface/SimpleTransmission</type>
  <joint name="fr3">
    <hardwareInterface>hardware_interface/EffortJointInterface</hardwareInterface>
  </joint>
  <actuator name="fr3_motor">
     <hardwareInterface>hardware_interface/EffortJointInterface</hardwareInterface>
      <mechanismReduction>1</mechanismReduction>
  </actuator>
</transmission>

<transmission name="fl3_trans">
  <type>transmission_interface/SimpleTransmission</type>
  <joint name="fl3">
    <hardwareInterface>hardware_interface/EffortJointInterface</hardwareInterface>
  </joint>
  <actuator name="fl3_motor">
     <hardwareInterface>hardware_interface/EffortJointInterface</hardwareInterface>
      <mechanismReduction>1</mechanismReduction>
  </actuator>
</transmission>

<transmission name="br3_trans">
  <type>transmission_interface/SimpleTransmission</type>
  <joint name="br3">
    <hardwareInterface>hardware_interface/EffortJointInterface</hardwareInterface>
  </joint>
  <actuator name="br3_motor">
     <hardwareInterface>hardware_interface/EffortJointInterface</hardwareInterface>
      <mechanismReduction>1</mechanismReduction>
  </actuator>
</transmission>

<transmission name="bl3_trans">
  <type>transmission_interface/SimpleTransmission</type>
  <joint name="bl3">
    <hardwareInterface>hardware_interface/EffortJointInterface</hardwareInterface>
  </joint>
  <actuator name="bl3_motor">
     <hardwareInterface>hardware_interface/EffortJointInterface</hardwareInterface>
      <mechanismReduction>1</mechanismReduction>
  </actuator>
</transmission>

<gazebo>
    <plugin name="gazebo_ros_control" filename="libgazebo_ros_control.so">
      <robotNamespace>/kamuy2</robotNamespace>
      <robotSimType>gazebo_ros_control/DefaultRobotHWSim</robotSimType>
      <legacyModeNS>true</legacyModeNS>
    </plugin>
</gazebo> -->

</robot>
