<?xml version="1.0" ?>
<!-- =================================================================================== -->
<!-- |    This document was autogenerated by xacro from kamuy2_legged.xacro            | -->
<!-- |    EDITING THIS FILE BY HAND IS NOT RECOMMENDED                                 | -->
<!-- =================================================================================== -->
<robot name="kamuy2">
  <material name="silver">
    <color rgba="0.700 0.700 0.700 1.000"/>
  </material>
  <!-- ros_control plugin -->
  <gazebo>
    <plugin filename="liblegged_hw_sim.so" name="gazebo_ros_control">
      <robotNamespace>/</robotNamespace>
      <robotParam>legged_robot_description</robotParam>
      <robotSimType>legged_gazebo/LeggedHWSim</robotSimType>
    </plugin>
  </gazebo>
  <gazebo>
    <plugin filename="libgazebo_ros_p3d.so" name="p3d_base_controller">
      <alwaysOn>true</alwaysOn>
      <updateRate>1000.0</updateRate>
      <bodyName>base</bodyName>
      <topicName>ground_truth/state</topicName>
      <gaussianNoise>0</gaussianNoise>
      <frameName>world</frameName>
      <xyzOffsets>0 0 0</xyzOffsets>
      <rpyOffsets>0 0 0</rpyOffsets>
    </plugin>
  </gazebo>
  <gazebo reference="base_link">
    <maxVel>100.</maxVel>
    <kp>10000.</kp>
    <kd>0.</kd>
  </gazebo>
  <gazebo reference="stick_link">
    <mu1>0.2</mu1>
    <mu2>0.2</mu2>
    <material>Gazebo/White</material>
  </gazebo>
  <!-- LF leg -->
  <gazebo reference="LF_hip">
    <mu1>0.2</mu1>
    <mu2>0.2</mu2>
    <material>Gazebo/DarkGrey</material>
  </gazebo>
  <gazebo reference="LF_thigh">
    <mu1>0.2</mu1>
    <mu2>0.2</mu2>
    <self_collide>0</self_collide>
    <material>Gazebo/DarkGrey</material>
    <kp value="1000000.0"/>
    <kd value="1.0"/>
  </gazebo>
  <gazebo reference="LF_calf">
    <mu1>0.2</mu1>
    <mu2>0.2</mu2>
    <self_collide>1</self_collide>
  </gazebo>
  <gazebo reference="LF_FOOT">
    <mu1>0.6</mu1>
    <mu2>0.6</mu2>
    <self_collide>1</self_collide>
    <material>Gazebo/DarkGrey</material>
    <kp value="1000000.0"/>
    <kd value="100.0"/>
  </gazebo>
  <!-- RF leg -->
  <gazebo reference="RF_hip">
    <mu1>0.2</mu1>
    <mu2>0.2</mu2>
    <material>Gazebo/DarkGrey</material>
  </gazebo>
  <gazebo reference="RF_thigh">
    <mu1>0.2</mu1>
    <mu2>0.2</mu2>
    <self_collide>0</self_collide>
    <material>Gazebo/DarkGrey</material>
    <kp value="1000000.0"/>
    <kd value="1.0"/>
  </gazebo>
  <gazebo reference="RF_calf">
    <mu1>0.2</mu1>
    <mu2>0.2</mu2>
    <self_collide>1</self_collide>
  </gazebo>
  <gazebo reference="RF_FOOT">
    <mu1>0.6</mu1>
    <mu2>0.6</mu2>
    <self_collide>1</self_collide>
    <material>Gazebo/DarkGrey</material>
    <kp value="1000000.0"/>
    <kd value="1.0"/>
  </gazebo>
  <!-- LH leg -->
  <gazebo reference="LH_hip">
    <mu1>0.2</mu1>
    <mu2>0.2</mu2>
    <material>Gazebo/DarkGrey</material>
  </gazebo>
  <gazebo reference="LH_thigh">
    <mu1>0.2</mu1>
    <mu2>0.2</mu2>
    <self_collide>0</self_collide>
    <material>Gazebo/DarkGrey</material>
    <kp value="1000000.0"/>
    <kd value="1.0"/>
  </gazebo>
  <gazebo reference="LH_calf">
    <mu1>0.2</mu1>
    <mu2>0.2</mu2>
    <self_collide>1</self_collide>
  </gazebo>
  <gazebo reference="LH_FOOT">
    <mu1>0.6</mu1>
    <mu2>0.6</mu2>
    <self_collide>1</self_collide>
    <material>Gazebo/DarkGrey</material>
    <kp value="1000000.0"/>
    <kd value="1.0"/>
  </gazebo>
  <!-- RH leg -->
  <gazebo reference="RH_hip">
    <mu1>0.2</mu1>
    <mu2>0.2</mu2>
    <material>Gazebo/DarkGrey</material>
  </gazebo>
  <gazebo reference="RH_thigh">
    <mu1>0.2</mu1>
    <mu2>0.2</mu2>
    <self_collide>0</self_collide>
    <material>Gazebo/DarkGrey</material>
    <kp value="1000000.0"/>
    <kd value="1.0"/>
  </gazebo>
  <gazebo reference="RH_calf">
    <mu1>0.2</mu1>
    <mu2>0.2</mu2>
    <self_collide>1</self_collide>
  </gazebo>
  <gazebo reference="RH_FOOT">
    <mu1>0.6</mu1>
    <mu2>0.6</mu2>
    <self_collide>1</self_collide>
    <material>Gazebo/DarkGrey</material>
    <kp value="1000000.0"/>
    <kd value="1.0"/>
  </gazebo>
  <!-- <xacro:include filename="$(find realsense2_description)/urdf/_d435.urdf.xacro"/> -->
  <link name="base">
    <inertial>
      <origin rpy="0 0 0" xyz="0 -0.005 0.1"/>
      <mass value="5"/>
      <inertia ixx="0.01354" ixy="0.0" ixz="0" iyy="0.1083" iyz="0" izz="0.11354"/>
    </inertial>
    <visual>
      <origin rpy="0 0 0" xyz="0 -0.005 0.03"/>
      <geometry>
        <mesh filename="/home/sato/kamuy2_ws/src/kamuy2_description/meshes/base_link.stl" scale="0.001 0.001 0.001"/>
      </geometry>
      <material name="silver"/>
    </visual>
    <collision>
      <origin rpy="0 0 0" xyz="0 -0.005 0.12"/>
      <geometry>
        <box size="0.5 0.15 0.1"/>
      </geometry>
    </collision>
  </link>
  <!-- Imu is fixed to the base link -->
  <joint name="unitree_imu_joint" type="fixed">
    <origin rpy="0. 0. 0." xyz="0. 0. 0."/>
    <parent link="base"/>
    <child link="unitree_imu"/>
  </joint>
  <!-- Imu link -->
  <link name="unitree_imu">
    <inertial>
      <mass value="0.01"/>
      <origin rpy="0 0 0" xyz="0 0 0"/>
      <inertia ixx="0.000001" ixy="0" ixz="0" iyy="0.000001" iyz="0" izz="0.000001"/>
    </inertial>
    <visual>
      <origin rpy="0 0 0" xyz="0 0 0"/>
      <geometry>
        <box size="0.015 0.015 0.004"/>
      </geometry>
    </visual>
    <material name="orange">
      <color rgba="255 108 10 255"/>
    </material>
  </link>
  <gazebo reference="unitree_imu">
    <material>Gazebo/Orange</material>
  </gazebo>
  <gazebo reference="unitree_imu_joint">
    <disableFixedJointLumping>true</disableFixedJointLumping>
  </gazebo>
  <!-- <xacro:sensor_d435 name="camera" parent="base" publish_pointcloud="true">
    <origin xyz="0.307 0 0.1" rpy="0 0.392699 0" />
</xacro:sensor_d435>  -->
  <!-- <link name="imu_link">

  <visual>
    <origin xyz="0 0.0 0" rpy="0 0 0"/>
    <geometry>
      <sphere radius="0.05"/>
    </geometry>
    <material name="silver"/>
  </visual>
</link> -->
  <!-- <link name="lidar_link">

  <visual>
    <origin xyz="0 0.0 0" rpy="0 0 0"/>
    <geometry>
      <sphere radius="0.05"/>
    </geometry>
    <material name="silver"/>
  </visual>
</link> -->
  <!-- second link -->
  <link name="LF_thigh">
    <inertial>
      <origin rpy="0 0 0" xyz="0 0 -0.1"/>
      <mass value="0.5"/>
      <inertia ixx="0.002403333333333" ixy="0.0" ixz="0" iyy="0.002403333333333" iyz="0" izz="0.00014"/>
    </inertial>
    <visual>
      <origin rpy="0 1.570796 0" xyz="0 0 0"/>
      <geometry>
        <mesh filename="/home/sato/kamuy2_ws/src/kamuy2_description/meshes/front_left_link_second.stl" scale="0.001 0.001 0.001"/>
      </geometry>
      <material name="silver"/>
    </visual>
    <collision>
      <origin rpy="0 0 0" xyz="0 0 -0.1"/>
      <geometry>
        <cylinder length="0.2" radius="0.02"/>
      </geometry>
    </collision>
  </link>
  <link name="LH_thigh">
    <inertial>
      <origin rpy="0 0 0" xyz="0 0 -0.1"/>
      <mass value="0.5"/>
      <inertia ixx="0.002403333333333" ixy="0.0" ixz="0" iyy="0.002403333333333" iyz="0" izz="0.00014"/>
    </inertial>
    <visual>
      <origin rpy="0 1.570796 0" xyz="0 0 0"/>
      <geometry>
        <mesh filename="/home/sato/kamuy2_ws/src/kamuy2_description/meshes/back_left_link_second.stl" scale="0.001 0.001 0.001"/>
      </geometry>
      <material name="silver"/>
    </visual>
    <collision>
      <origin rpy="0 0 0" xyz="0 0 -0.1"/>
      <geometry>
        <cylinder length="0.2" radius="0.02"/>
      </geometry>
    </collision>
  </link>
  <link name="RF_thigh">
    <inertial>
      <origin rpy="0 0 0" xyz="0 0 -0.1"/>
      <mass value="0.5"/>
      <inertia ixx="0.002403333333333" ixy="0.0" ixz="0" iyy="0.002403333333333" iyz="0" izz="0.00014"/>
    </inertial>
    <visual>
      <origin rpy="0 1.570796 0" xyz="0 0 0"/>
      <geometry>
        <mesh filename="/home/sato/kamuy2_ws/src/kamuy2_description/meshes/front_right_link_second.stl" scale="0.001 0.001 0.001"/>
      </geometry>
      <material name="silver"/>
    </visual>
    <collision>
      <origin rpy="0 0 0" xyz="0 0 -0.1"/>
      <geometry>
        <cylinder length="0.2" radius="0.02"/>
      </geometry>
    </collision>
  </link>
  <link name="RH_thigh">
    <inertial>
      <origin rpy="0 0 0" xyz="0 0 -0.1"/>
      <mass value="0.5"/>
      <inertia ixx="0.002403333333333" ixy="0.0" ixz="0" iyy="0.002403333333333" iyz="0" izz="0.00014"/>
    </inertial>
    <visual>
      <origin rpy="0 1.570796 0" xyz="0 0 0"/>
      <geometry>
        <mesh filename="/home/sato/kamuy2_ws/src/kamuy2_description/meshes/back_right_link_second.stl" scale="0.001 0.001 0.001"/>
      </geometry>
      <material name="silver"/>
    </visual>
    <collision>
      <origin rpy="0 0 0" xyz="0 0 -0.1"/>
      <geometry>
        <cylinder length="0.2" radius="0.02"/>
      </geometry>
    </collision>
  </link>
  <!-- first link -->
  <link name="RF_hip">
    <inertial>
      <origin rpy="0 0 0" xyz="0 0 0"/>
      <mass value="1.4"/>
      <inertia ixx="0.001058" ixy="0" ixz="0" iyy="0.002404" iyz="0" izz="0.002404"/>
    </inertial>
    <visual>
      <origin rpy="0 0 3.141592" xyz="0 0 0"/>
      <geometry>
        <mesh filename="/home/sato/kamuy2_ws/src/kamuy2_description/meshes/front_right_link_first.stl" scale="0.001 0.001 0.001"/>
      </geometry>
      <material name="silver"/>
    </visual>
    <collision>
      <origin rpy="0 1.570796 3.141592" xyz="0 0 0"/>
      <geometry>
        <cylinder length="0.15" radius="0.046"/>
      </geometry>
    </collision>
  </link>
  <link name="LF_hip">
    <inertial>
      <origin rpy="0 0 0" xyz="0 0 0"/>
      <mass value="1.4"/>
      <inertia ixx="0.001058" ixy="0" ixz="0" iyy="0.002404" iyz="0" izz="0.002404"/>
    </inertial>
    <visual>
      <origin rpy="0 0 3.141592" xyz="0 0 0"/>
      <geometry>
        <mesh filename="/home/sato/kamuy2_ws/src/kamuy2_description/meshes/front_left_link_first.stl" scale="0.001 0.001 0.001"/>
      </geometry>
      <material name="silver"/>
    </visual>
    <collision>
      <origin rpy="0 1.570796 3.141592" xyz="0 0 0"/>
      <geometry>
        <cylinder length="0.15" radius="0.046"/>
      </geometry>
    </collision>
  </link>
  <link name="RH_hip">
    <inertial>
      <origin rpy="0 0 0" xyz="0 0 0"/>
      <mass value="1.4"/>
      <inertia ixx="0.001058" ixy="0" ixz="0" iyy="0.002404" iyz="0" izz="0.002404"/>
    </inertial>
    <visual>
      <origin rpy="0 0 0" xyz="0 0 0"/>
      <geometry>
        <mesh filename="/home/sato/kamuy2_ws/src/kamuy2_description/meshes/back_right_link_first.stl" scale="0.001 0.001 0.001"/>
      </geometry>
      <material name="silver"/>
    </visual>
    <collision>
      <origin rpy="0 1.570796 0" xyz="0 0 0"/>
      <geometry>
        <cylinder length="0.15" radius="0.046"/>
      </geometry>
    </collision>
  </link>
  <link name="LH_hip">
    <inertial>
      <origin rpy="0 0 0" xyz="0 0 0"/>
      <mass value="1.4"/>
      <inertia ixx="0.001058" ixy="0" ixz="0" iyy="0.002404" iyz="0" izz="0.002404"/>
    </inertial>
    <visual>
      <origin rpy="0 0 0" xyz="0 0 0"/>
      <geometry>
        <mesh filename="/home/sato/kamuy2_ws/src/kamuy2_description/meshes/back_left_link_first.stl" scale="0.001 0.001 0.001"/>
      </geometry>
      <material name="silver"/>
    </visual>
    <collision>
      <origin rpy="0 1.570796 0" xyz="0 0 0"/>
      <geometry>
        <cylinder length="0.15" radius="0.046"/>
      </geometry>
    </collision>
  </link>
  <!-- foot -->
  <link name="LH_calf">
    <inertial>
      <origin rpy="0 0 0" xyz="-0.05 0 -0.1"/>
      <mass value="0.5"/>
      <inertia ixx="0.001716666666667" ixy="0" ixz="0" iyy="0.001716666666667" iyz="0" izz="0.0001"/>
    </inertial>
    <visual>
      <origin rpy="0 1.570796 0" xyz="0 0 0"/>
      <geometry>
        <mesh filename="/home/sato/kamuy2_ws/src/kamuy2_description/meshes/back_left_link_foot.stl" scale="0.001 0.001 0.001"/>
      </geometry>
      <material name="silver"/>
    </visual>
    <collision>
      <origin rpy="0 1.570796 0" xyz="-0.05 0 -0.1"/>
      <geometry>
        <box size="0.2 0.016 0.016"/>
      </geometry>
    </collision>
  </link>
  <link name="LF_calf">
    <inertial>
      <origin rpy="0 0 0" xyz="-0.05 0 -0.1"/>
      <mass value="0.5"/>
      <inertia ixx="0.001716666666667" ixy="0" ixz="0" iyy="0.001716666666667" iyz="0" izz="0.0001"/>
    </inertial>
    <visual>
      <origin rpy="0 1.570796 0" xyz="0 0 0"/>
      <geometry>
        <mesh filename="/home/sato/kamuy2_ws/src/kamuy2_description/meshes/front_left_link_foot.stl" scale="0.001 0.001 0.001"/>
      </geometry>
      <material name="silver"/>
    </visual>
    <collision>
      <origin rpy="0 1.570796 0" xyz="-0.05 0 -0.1"/>
      <geometry>
        <box size="0.2 0.016 0.016"/>
      </geometry>
    </collision>
  </link>
  <link name="RF_calf">
    <inertial>
      <origin rpy="3.141592 0 0" xyz="-0.05 0 -0.1"/>
      <mass value="0.5"/>
      <inertia ixx="0.001716666666667" ixy="0" ixz="0" iyy="0.001716666666667" iyz="0" izz="0.0001"/>
    </inertial>
    <visual>
      <origin rpy="3.141592 1.570796 0" xyz="0 0 0"/>
      <geometry>
        <mesh filename="/home/sato/kamuy2_ws/src/kamuy2_description/meshes/front_right_link_foot.stl" scale="0.001 0.001 0.001"/>
      </geometry>
      <material name="silver"/>
    </visual>
    <collision>
      <origin rpy="3.141592 1.570796 0" xyz="-0.05 0 -0.1"/>
      <geometry>
        <box size="0.2 0.016 0.016"/>
      </geometry>
    </collision>
  </link>
  <link name="RH_calf">
    <inertial>
      <origin rpy="3.141592 0 0" xyz="-0.05 0 -0.1"/>
      <mass value="0.5"/>
      <inertia ixx="0.001716666666667" ixy="0" ixz="0" iyy="0.001716666666667" iyz="0" izz="0.0001"/>
    </inertial>
    <visual>
      <origin rpy="3.141592 1.570796 0" xyz="0 0 0"/>
      <geometry>
        <mesh filename="/home/sato/kamuy2_ws/src/kamuy2_description/meshes/back_right_link_foot.stl" scale="0.001 0.001 0.001"/>
      </geometry>
      <material name="silver"/>
    </visual>
    <collision>
      <origin rpy="3.141592 1.570796 0" xyz="-0.05 0 -0.1"/>
      <geometry>
        <box size="0.2 0.016 0.016"/>
      </geometry>
    </collision>
  </link>
  <link name="LF_FOOT">
    <inertial>
      <origin rpy="0 0 0" xyz="0 0 0"/>
      <mass value="0.1"/>
      <inertia ixx="9.600000000000001e-06" ixy="0.0" ixz="0.0" iyy="9.600000000000001e-06" iyz="0.0" izz="9.600000000000001e-06"/>
    </inertial>
    <visual>
      <geometry>
        <sphere radius="0.04"/>
      </geometry>
    </visual>
    <collision>
      <geometry>
        <sphere radius="0.04"/>
      </geometry>
      <surface>
        <friction>
          <ode>
            <mu>10</mu>
            <mu2>10</mu2>
          </ode>
        </friction>
      </surface>
    </collision>
  </link>
  <link name="RF_FOOT">
    <inertial>
      <origin rpy="0 0 0" xyz="0 0 0"/>
      <mass value="0.1"/>
      <inertia ixx="9.600000000000001e-06" ixy="0.0" ixz="0.0" iyy="9.600000000000001e-06" iyz="0.0" izz="9.600000000000001e-06"/>
    </inertial>
    <visual>
      <geometry>
        <sphere radius="0.04"/>
      </geometry>
    </visual>
    <collision>
      <geometry>
        <sphere radius="0.04"/>
      </geometry>
      <surface>
        <friction>
          <ode>
            <mu>10</mu>
            <mu2>10</mu2>
          </ode>
        </friction>
      </surface>
    </collision>
  </link>
  <link name="LH_FOOT">
    <inertial>
      <origin rpy="0 0 0" xyz="0 0 0"/>
      <mass value="0.1"/>
      <inertia ixx="9.600000000000001e-06" ixy="0.0" ixz="0.0" iyy="9.600000000000001e-06" iyz="0.0" izz="9.600000000000001e-06"/>
    </inertial>
    <visual>
      <geometry>
        <sphere radius="0.04"/>
      </geometry>
    </visual>
    <collision>
      <geometry>
        <sphere radius="0.04"/>
      </geometry>
      <surface>
        <friction>
          <ode>
            <mu>10</mu>
            <mu2>10</mu2>
          </ode>
        </friction>
      </surface>
    </collision>
  </link>
  <link name="RH_FOOT">
    <inertial>
      <origin rpy="0 0 0" xyz="0 0 0"/>
      <mass value="0.1"/>
      <inertia ixx="9.600000000000001e-06" ixy="0.0" ixz="0.0" iyy="9.600000000000001e-06" iyz="0.0" izz="9.600000000000001e-06"/>
    </inertial>
    <visual>
      <geometry>
        <sphere radius="0.04"/>
      </geometry>
    </visual>
    <collision>
      <geometry>
        <sphere radius="0.04"/>
      </geometry>
      <surface>
        <friction>
          <ode>
            <mu>10</mu>
            <mu2>10</mu2>
          </ode>
        </friction>
      </surface>
    </collision>
  </link>
  <joint name="RF_HAA" type="revolute">
    <origin rpy="0 0 0" xyz="0.200441 -0.065042 0.030961"/>
    <parent link="base"/>
    <child link="RF_hip"/>
    <axis xyz="1.0 0.0 0.0"/>
    <dynamics damping="0" friction="0"/>
    <limit effort="20" lower="-0.785398" upper="0.785398" velocity="10"/>
  </joint>
  <joint name="LF_HAA" type="revolute">
    <origin rpy="0 0 0" xyz="0.200441 0.065042 0.030961"/>
    <parent link="base"/>
    <child link="LF_hip"/>
    <axis xyz="1.0 0.0 0.0"/>
    <dynamics damping="0" friction="0"/>
    <limit effort="20" lower="-0.785398" upper="0.785398" velocity="10"/>
  </joint>
  <joint name="RH_HAA" type="revolute">
    <origin rpy="0 0 0" xyz="-0.200441 -0.06509 0.030961"/>
    <parent link="base"/>
    <child link="RH_hip"/>
    <axis xyz="1.0 0 -0.0"/>
    <dynamics damping="0" friction="0"/>
    <limit effort="20" lower="-0.785398" upper="0.785398" velocity="10"/>
  </joint>
  <joint name="LH_HAA" type="revolute">
    <origin rpy="0 0 0" xyz="-0.200441 0.065042 0.030961"/>
    <parent link="base"/>
    <child link="LH_hip"/>
    <axis xyz="1.0 0 -0.0"/>
    <dynamics damping="0" friction="0"/>
    <limit effort="20" lower="-0.785398" upper="0.785398" velocity="10"/>
  </joint>
  <joint name="LF_HFE" type="revolute">
    <origin rpy="0 1 0" xyz="0 0.094475 0"/>
    <parent link="LF_hip"/>
    <child link="LF_thigh"/>
    <axis xyz="0.0 1.0 0.0"/>
    <dynamics damping="0" friction="0"/>
    <limit effort="20" lower="0.0" upper="3.141593" velocity="10"/>
  </joint>
  <joint name="LH_HFE" type="revolute">
    <origin rpy="0 1 0" xyz="0 0.094475 0"/>
    <parent link="LH_hip"/>
    <child link="LH_thigh"/>
    <axis xyz="0.0 1.0 0.0"/>
    <dynamics damping="0" friction="0"/>
    <limit effort="20" lower="0.0" upper="3.141593" velocity="10"/>
  </joint>
  <joint name="RF_HFE" type="revolute">
    <origin rpy="0 1 0" xyz="0 -0.078675 0"/>
    <parent link="RF_hip"/>
    <child link="RF_thigh"/>
    <axis xyz="-0.0 1.0 -0.0"/>
    <dynamics damping="0" friction="0"/>
    <limit effort="20" lower="0.0" upper="3.141593" velocity="10"/>
  </joint>
  <joint name="RH_HFE" type="revolute">
    <origin rpy="0 1 0" xyz="0 -0.086575 0"/>
    <parent link="RH_hip"/>
    <child link="RH_thigh"/>
    <axis xyz="-0.0 1.0 -0.0"/>
    <dynamics damping="0" friction="0"/>
    <limit effort="20" lower="0.0" upper="3.141593" velocity="10"/>
  </joint>
  <joint name="LH_KFE" type="revolute">
    <origin rpy="0 -2 0" xyz=" 0 0 -0.200"/>
    <parent link="LH_thigh"/>
    <child link="LH_calf"/>
    <axis xyz="0 1 -0.0"/>
    <dynamics damping="0" friction="0"/>
    <limit effort="20" lower="-3.141592" upper="0" velocity="10"/>
  </joint>
  <joint name="LF_KFE" type="revolute">
    <origin rpy="0 -2 0" xyz="0 0 -0.200 "/>
    <parent link="LF_thigh"/>
    <child link="LF_calf"/>
    <axis xyz="-0.0 1.0 -0.0"/>
    <dynamics damping="0" friction="0"/>
    <limit effort="20" lower="-3.141592" upper="0" velocity="10"/>
  </joint>
  <joint name="RF_KFE" type="revolute">
    <origin rpy="0 -2 0" xyz="0 0 -0.200 "/>
    <parent link="RF_thigh"/>
    <child link="RF_calf"/>
    <axis xyz="0.0 1.0 0.0"/>
    <dynamics damping="0" friction="0"/>
    <limit effort="20" lower="-3.141592" upper="0" velocity="10"/>
  </joint>
  <joint name="RH_KFE" type="revolute">
    <origin rpy="0 -2 0" xyz="0 0 -0.200 "/>
    <parent link="RH_thigh"/>
    <child link="RH_calf"/>
    <axis xyz="0 1.0 -0.0"/>
    <dynamics damping="0" friction="0"/>
    <limit effort="20" lower="-3.141592" upper="0" velocity="10"/>
  </joint>
  <joint name="LF_foot_fixed" type="fixed">
    <origin rpy="0 0 0" xyz="-0.05 0 -0.22"/>
    <parent link="LF_calf"/>
    <child link="LF_FOOT"/>
    <axis xyz="0.0 1.0 -0.0"/>
    <dynamics damping="0" friction="0"/>
    <limit effort="20" lower="0.0" upper="3.141593" velocity="10"/>
  </joint>
  <joint name="RF_foot_fixed" type="fixed">
    <origin rpy="0 0 0" xyz="-0.05 0 -0.22 "/>
    <parent link="RF_calf"/>
    <child link="RF_FOOT"/>
    <axis xyz="0.0 1.0 -0.0"/>
    <dynamics damping="0" friction="0"/>
    <limit effort="20" lower="0.0" upper="3.141593" velocity="10"/>
  </joint>
  <joint name="LH_foot_fixed" type="fixed">
    <origin rpy="0 0 0" xyz="-0.05 0 -0.22"/>
    <parent link="LH_calf"/>
    <child link="LH_FOOT"/>
    <axis xyz="0.0 1.0 -0.0"/>
    <dynamics damping="0" friction="0"/>
    <limit effort="20" lower="0.0" upper="3.141593" velocity="10"/>
  </joint>
  <joint name="RH_foot_fixed" type="fixed">
    <origin rpy="0 0 0" xyz="-0.05 0 -0.22"/>
    <parent link="RH_calf"/>
    <child link="RH_FOOT"/>
    <axis xyz="-0.0 -1.0 -0.0"/>
    <dynamics damping="0" friction="0"/>
    <limit effort="20" lower="0.0" upper="3.141593" velocity="10"/>
  </joint>
  <!-- <joint name="camera_joint" type="fixed">
 <origin xyz="0.3 0 0" rpy="0 0 0"/>
  <parent link="base"/>
  <child link="camera_link"/>
  <axis xyz="0 0 0"/>
</joint> -->
  <!-- <joint name="imu_joint" type="fixed">
 <origin xyz="0 0 0" rpy="0 0 0"/>
  <parent link="base"/>
  <child link="imu_link"/>
  <axis xyz="0 0 0"/>
</joint>

<gazebo>
    <plugin filename="libhector_gazebo_ros_imu.so" name="imu_controller">
      <updateRate>50.0</updateRate>
      <bodyName>imu_link</bodyName>
      <topicName>imu/data</topicName>
      <accelDrift>0.005 0.005 0.005</accelDrift>
      <accelGaussianNoise>0.005 0.005 0.005</accelGaussianNoise>
      <rateDrift>0.005 0.005 0.005 </rateDrift>
      <rateGaussianNoise>0.005 0.005 0.005 </rateGaussianNoise>
      <headingDrift>0.005</headingDrift>
      <headingGaussianNoise>0.005</headingGaussianNoise>
    </plugin>
  </gazebo> -->
  <!-- <joint name="lidar_joint" type="fixed">
 <origin xyz="0 0 0" rpy="0 0 0"/>
  <parent link="base"/>
  <child link="lidar_link"/>
  <axis xyz="0 0 0.3"/>
</joint> -->
  <gazebo reference="LF_foot_fixed">
    <disableFixedJointLumping>true</disableFixedJointLumping>
  </gazebo>
  <transmission name="LF_HAA_tran">
    <type>transmission_interface/SimpleTransmission</type>
    <joint name="LF_HAA">
      <hardwareInterface>hardware_interface/EffortJointInterface</hardwareInterface>
    </joint>
    <actuator name="LF_HAA_motor">
      <hardwareInterface>hardware_interface/EffortJointInterface</hardwareInterface>
      <mechanicalReduction>1</mechanicalReduction>
    </actuator>
  </transmission>
  <transmission name="LF_HFE_tran">
    <type>transmission_interface/SimpleTransmission</type>
    <joint name="LF_HFE">
      <hardwareInterface>hardware_interface/EffortJointInterface</hardwareInterface>
    </joint>
    <actuator name="LF_HFE_motor">
      <hardwareInterface>hardware_interface/EffortJointInterface</hardwareInterface>
      <mechanicalReduction>1</mechanicalReduction>
    </actuator>
  </transmission>
  <transmission name="LF_KFE_tran">
    <type>transmission_interface/SimpleTransmission</type>
    <joint name="LF_KFE">
      <hardwareInterface>hardware_interface/EffortJointInterface</hardwareInterface>
    </joint>
    <actuator name="LF_KFE_motor">
      <hardwareInterface>hardware_interface/EffortJointInterface</hardwareInterface>
      <mechanicalReduction>1</mechanicalReduction>
    </actuator>
  </transmission>
  <gazebo reference="RF_foot_fixed">
    <disableFixedJointLumping>true</disableFixedJointLumping>
  </gazebo>
  <transmission name="RF_HAA_tran">
    <type>transmission_interface/SimpleTransmission</type>
    <joint name="RF_HAA">
      <hardwareInterface>hardware_interface/EffortJointInterface</hardwareInterface>
    </joint>
    <actuator name="RF_HAA_motor">
      <hardwareInterface>hardware_interface/EffortJointInterface</hardwareInterface>
      <mechanicalReduction>1</mechanicalReduction>
    </actuator>
  </transmission>
  <transmission name="RF_HFE_tran">
    <type>transmission_interface/SimpleTransmission</type>
    <joint name="RF_HFE">
      <hardwareInterface>hardware_interface/EffortJointInterface</hardwareInterface>
    </joint>
    <actuator name="RF_HFE_motor">
      <hardwareInterface>hardware_interface/EffortJointInterface</hardwareInterface>
      <mechanicalReduction>1</mechanicalReduction>
    </actuator>
  </transmission>
  <transmission name="RF_KFE_tran">
    <type>transmission_interface/SimpleTransmission</type>
    <joint name="RF_KFE">
      <hardwareInterface>hardware_interface/EffortJointInterface</hardwareInterface>
    </joint>
    <actuator name="RF_KFE_motor">
      <hardwareInterface>hardware_interface/EffortJointInterface</hardwareInterface>
      <mechanicalReduction>1</mechanicalReduction>
    </actuator>
  </transmission>
  <gazebo reference="LH_foot_fixed">
    <disableFixedJointLumping>true</disableFixedJointLumping>
  </gazebo>
  <transmission name="LH_HAA_tran">
    <type>transmission_interface/SimpleTransmission</type>
    <joint name="LH_HAA">
      <hardwareInterface>hardware_interface/EffortJointInterface</hardwareInterface>
    </joint>
    <actuator name="LH_HAA_motor">
      <hardwareInterface>hardware_interface/EffortJointInterface</hardwareInterface>
      <mechanicalReduction>1</mechanicalReduction>
    </actuator>
  </transmission>
  <transmission name="LH_HFE_tran">
    <type>transmission_interface/SimpleTransmission</type>
    <joint name="LH_HFE">
      <hardwareInterface>hardware_interface/EffortJointInterface</hardwareInterface>
    </joint>
    <actuator name="LH_HFE_motor">
      <hardwareInterface>hardware_interface/EffortJointInterface</hardwareInterface>
      <mechanicalReduction>1</mechanicalReduction>
    </actuator>
  </transmission>
  <transmission name="LH_KFE_tran">
    <type>transmission_interface/SimpleTransmission</type>
    <joint name="LH_KFE">
      <hardwareInterface>hardware_interface/EffortJointInterface</hardwareInterface>
    </joint>
    <actuator name="LH_KFE_motor">
      <hardwareInterface>hardware_interface/EffortJointInterface</hardwareInterface>
      <mechanicalReduction>1</mechanicalReduction>
    </actuator>
  </transmission>
  <gazebo reference="RH_foot_fixed">
    <disableFixedJointLumping>true</disableFixedJointLumping>
  </gazebo>
  <transmission name="RH_HAA_tran">
    <type>transmission_interface/SimpleTransmission</type>
    <joint name="RH_HAA">
      <hardwareInterface>hardware_interface/EffortJointInterface</hardwareInterface>
    </joint>
    <actuator name="RH_HAA_motor">
      <hardwareInterface>hardware_interface/EffortJointInterface</hardwareInterface>
      <mechanicalReduction>1</mechanicalReduction>
    </actuator>
  </transmission>
  <transmission name="RH_HFE_tran">
    <type>transmission_interface/SimpleTransmission</type>
    <joint name="RH_HFE">
      <hardwareInterface>hardware_interface/EffortJointInterface</hardwareInterface>
    </joint>
    <actuator name="RH_HFE_motor">
      <hardwareInterface>hardware_interface/EffortJointInterface</hardwareInterface>
      <mechanicalReduction>1</mechanicalReduction>
    </actuator>
  </transmission>
  <transmission name="RH_KFE_tran">
    <type>transmission_interface/SimpleTransmission</type>
    <joint name="RH_KFE">
      <hardwareInterface>hardware_interface/EffortJointInterface</hardwareInterface>
    </joint>
    <actuator name="RH_KFE_motor">
      <hardwareInterface>hardware_interface/EffortJointInterface</hardwareInterface>
      <mechanicalReduction>1</mechanicalReduction>
    </actuator>
  </transmission>
</robot>
