<?xml version="1.0" ?>
<!-- =================================================================================== -->
<!-- |    This document was autogenerated by xacro from kamuy2.xacro                   | -->
<!-- |    EDITING THIS FILE BY HAND IS NOT RECOMMENDED                                 | -->
<!-- =================================================================================== -->
<robot name="kamuy2">
  <material name="silver">
    <color rgba="0.700 0.700 0.700 1.000"/>
  </material>
  <transmission name="fl2_tran">
    <type>transmission_interface/SimpleTransmission</type>
    <joint name="fl2">
      <hardwareInterface>hardware_interface/EffortJointInterface</hardwareInterface>
    </joint>
    <actuator name="fl2_actr">
      <hardwareInterface>hardware_interface/EffortJointInterface</hardwareInterface>
      <mechanicalReduction>1</mechanicalReduction>
    </actuator>
  </transmission>
  <transmission name="bl2_tran">
    <type>transmission_interface/SimpleTransmission</type>
    <joint name="bl2">
      <hardwareInterface>hardware_interface/EffortJointInterface</hardwareInterface>
    </joint>
    <actuator name="bl2_actr">
      <hardwareInterface>hardware_interface/EffortJointInterface</hardwareInterface>
      <mechanicalReduction>1</mechanicalReduction>
    </actuator>
  </transmission>
  <transmission name="fr2_tran">
    <type>transmission_interface/SimpleTransmission</type>
    <joint name="fr2">
      <hardwareInterface>hardware_interface/EffortJointInterface</hardwareInterface>
    </joint>
    <actuator name="fr2_actr">
      <hardwareInterface>hardware_interface/EffortJointInterface</hardwareInterface>
      <mechanicalReduction>1</mechanicalReduction>
    </actuator>
  </transmission>
  <transmission name="br2_tran">
    <type>transmission_interface/SimpleTransmission</type>
    <joint name="br2">
      <hardwareInterface>hardware_interface/EffortJointInterface</hardwareInterface>
    </joint>
    <actuator name="br2_actr">
      <hardwareInterface>hardware_interface/EffortJointInterface</hardwareInterface>
      <mechanicalReduction>1</mechanicalReduction>
    </actuator>
  </transmission>
  <transmission name="fr1_tran">
    <type>transmission_interface/SimpleTransmission</type>
    <joint name="fr1">
      <hardwareInterface>hardware_interface/EffortJointInterface</hardwareInterface>
    </joint>
    <actuator name="fr1_actr">
      <hardwareInterface>hardware_interface/EffortJointInterface</hardwareInterface>
      <mechanicalReduction>1</mechanicalReduction>
    </actuator>
  </transmission>
  <transmission name="fl1_tran">
    <type>transmission_interface/SimpleTransmission</type>
    <joint name="fl1">
      <hardwareInterface>hardware_interface/EffortJointInterface</hardwareInterface>
    </joint>
    <actuator name="fl1_actr">
      <hardwareInterface>hardware_interface/EffortJointInterface</hardwareInterface>
      <mechanicalReduction>1</mechanicalReduction>
    </actuator>
  </transmission>
  <transmission name="br1_tran">
    <type>transmission_interface/SimpleTransmission</type>
    <joint name="br1">
      <hardwareInterface>hardware_interface/EffortJointInterface</hardwareInterface>
    </joint>
    <actuator name="br1_actr">
      <hardwareInterface>hardware_interface/EffortJointInterface</hardwareInterface>
      <mechanicalReduction>1</mechanicalReduction>
    </actuator>
  </transmission>
  <transmission name="bl1_tran">
    <type>transmission_interface/SimpleTransmission</type>
    <joint name="bl1">
      <hardwareInterface>hardware_interface/EffortJointInterface</hardwareInterface>
    </joint>
    <actuator name="bl1_actr">
      <hardwareInterface>hardware_interface/EffortJointInterface</hardwareInterface>
      <mechanicalReduction>1</mechanicalReduction>
    </actuator>
  </transmission>
  <transmission name="bl3_tran">
    <type>transmission_interface/SimpleTransmission</type>
    <joint name="bl3">
      <hardwareInterface>hardware_interface/EffortJointInterface</hardwareInterface>
    </joint>
    <actuator name="bl3_actr">
      <hardwareInterface>hardware_interface/EffortJointInterface</hardwareInterface>
      <mechanicalReduction>1</mechanicalReduction>
    </actuator>
  </transmission>
  <transmission name="fl3_tran">
    <type>transmission_interface/SimpleTransmission</type>
    <joint name="fl3">
      <hardwareInterface>hardware_interface/EffortJointInterface</hardwareInterface>
    </joint>
    <actuator name="fl3_actr">
      <hardwareInterface>hardware_interface/EffortJointInterface</hardwareInterface>
      <mechanicalReduction>1</mechanicalReduction>
    </actuator>
  </transmission>
  <transmission name="fr3_tran">
    <type>transmission_interface/SimpleTransmission</type>
    <joint name="fr3">
      <hardwareInterface>hardware_interface/EffortJointInterface</hardwareInterface>
    </joint>
    <actuator name="fr3_actr">
      <hardwareInterface>hardware_interface/EffortJointInterface</hardwareInterface>
      <mechanicalReduction>1</mechanicalReduction>
    </actuator>
  </transmission>
  <transmission name="br3_tran">
    <type>transmission_interface/SimpleTransmission</type>
    <joint name="br3">
      <hardwareInterface>hardware_interface/EffortJointInterface</hardwareInterface>
    </joint>
    <actuator name="br3_actr">
      <hardwareInterface>hardware_interface/EffortJointInterface</hardwareInterface>
      <mechanicalReduction>1</mechanicalReduction>
    </actuator>
  </transmission>
  <gazebo>
    <plugin filename="libgazebo_ros_control.so" name="control"/>
  </gazebo>
  <gazebo reference="base_link">
    <material>Gazebo/Silver</material>
    <mu1>0.2</mu1>
    <mu2>0.2</mu2>
    <selfCollide>true</selfCollide>
    <gravity>true</gravity>
  </gazebo>
  <gazebo reference="front_left_link_second_1">
    <material>Gazebo/Silver</material>
    <mu1>0.2</mu1>
    <mu2>0.2</mu2>
    <selfCollide>true</selfCollide>
  </gazebo>
  <gazebo reference="back_left_link_second_1">
    <material>Gazebo/Silver</material>
    <mu1>0.2</mu1>
    <mu2>0.2</mu2>
    <selfCollide>true</selfCollide>
  </gazebo>
  <gazebo reference="front_right_link_second_1">
    <material>Gazebo/Silver</material>
    <mu1>0.2</mu1>
    <mu2>0.2</mu2>
    <selfCollide>true</selfCollide>
  </gazebo>
  <gazebo reference="back_right_link_second_1">
    <material>Gazebo/Silver</material>
    <mu1>0.2</mu1>
    <mu2>0.2</mu2>
    <selfCollide>true</selfCollide>
  </gazebo>
  <gazebo reference="front_right_link_first_1">
    <material>Gazebo/Silver</material>
    <mu1>0.2</mu1>
    <mu2>0.2</mu2>
    <selfCollide>true</selfCollide>
  </gazebo>
  <gazebo reference="front_left_link_first_1">
    <material>Gazebo/Silver</material>
    <mu1>0.2</mu1>
    <mu2>0.2</mu2>
    <selfCollide>true</selfCollide>
  </gazebo>
  <gazebo reference="back_right_link_first_1">
    <material>Gazebo/Silver</material>
    <mu1>0.2</mu1>
    <mu2>0.2</mu2>
    <selfCollide>true</selfCollide>
  </gazebo>
  <gazebo reference="back_left_link_first_1">
    <material>Gazebo/Silver</material>
    <mu1>0.2</mu1>
    <mu2>0.2</mu2>
    <selfCollide>true</selfCollide>
  </gazebo>
  <gazebo reference="back_left_link_foot_1">
    <material>Gazebo/Silver</material>
    <mu1>0.2</mu1>
    <mu2>0.2</mu2>
    <selfCollide>true</selfCollide>
  </gazebo>
  <gazebo reference="front_left_link_foot_1">
    <material>Gazebo/Silver</material>
    <mu1>0.2</mu1>
    <mu2>0.2</mu2>
    <selfCollide>true</selfCollide>
  </gazebo>
  <gazebo reference="front_right_link_foot_1">
    <material>Gazebo/Silver</material>
    <mu1>0.2</mu1>
    <mu2>0.2</mu2>
    <selfCollide>true</selfCollide>
  </gazebo>
  <gazebo reference="back_right_link_foot_1">
    <material>Gazebo/Silver</material>
    <mu1>0.2</mu1>
    <mu2>0.2</mu2>
    <selfCollide>true</selfCollide>
  </gazebo>
  <link name="base_link">
    <inertial>
      <origin rpy="0 0 0" xyz="0.00025193197119904756 0.0011290062234152254 0.10689635737270876"/>
      <mass value="10"/>
      <inertia ixx="0.0666" ixy="0.0" ixz="0" iyy="0.24166" iyz="0" izz="0.24166"/>
    </inertial>
    <visual>
      <origin rpy="0 0 0" xyz="0 0 0.03"/>
      <geometry>
        <mesh filename="package://kamuy2_description/meshes/base_link.stl" scale="0.001 0.001 0.001"/>
      </geometry>
      <material name="silver"/>
    </visual>
    <collision>
      <origin rpy="0 0 0" xyz="0 0 0.03"/>
      <geometry>
        <mesh filename="package://kamuy2_description/meshes/base_link.stl" scale="0.001 0.001 0.001"/>
      </geometry>
    </collision>
  </link>
  <!-- second link -->
  <link name="front_left_link_second">
    <inertial>
      <origin rpy="0 1.570796 0" xyz="0 0 0"/>
      <mass value="0.5"/>
      <inertia ixx="0.00712" ixy="0.0" ixz="0" iyy="0.007101" iyz="0" izz="0.000185416"/>
    </inertial>
    <visual>
      <origin rpy="0 1.570796 0" xyz="0 0 0"/>
      <geometry>
        <mesh filename="package://kamuy2_description/meshes/front_left_link_second.stl" scale="0.001 0.001 0.001"/>
      </geometry>
      <material name="silver"/>
    </visual>
    <collision>
      <origin rpy="0 1.570796 0" xyz="0 0 0"/>
      <geometry>
        <mesh filename="package://kamuy2_description/meshes/front_left_link_second.stl" scale="0.001 0.001 0.001"/>
      </geometry>
    </collision>
  </link>
  <link name="back_left_link_second">
    <inertial>
      <origin rpy="0 1.570796 0" xyz="0 0 0"/>
      <mass value="0.5"/>
      <inertia ixx="0.00712" ixy="0.0" ixz="0" iyy="0.007101" iyz="0" izz="0.000185416"/>
    </inertial>
    <visual>
      <origin rpy="0 1.570796 0" xyz="0 0 0"/>
      <geometry>
        <mesh filename="package://kamuy2_description/meshes/back_left_link_second.stl" scale="0.001 0.001 0.001"/>
      </geometry>
      <material name="silver"/>
    </visual>
    <collision>
      <origin rpy="0 1.570796 0" xyz="0 0 0"/>
      <geometry>
        <mesh filename="package://kamuy2_description/meshes/back_left_link_second.stl" scale="0.001 0.001 0.001"/>
      </geometry>
    </collision>
  </link>
  <link name="front_right_link_second">
    <inertial>
      <origin rpy="0 1.570796 0" xyz="0 0 0"/>
      <mass value="0.5"/>
      <inertia ixx="0.00712" ixy="0.0" ixz="0" iyy="0.007101" iyz="0" izz="0.000185416"/>
    </inertial>
    <visual>
      <origin rpy="0 1.570796 0" xyz="0 0 0"/>
      <geometry>
        <mesh filename="package://kamuy2_description/meshes/front_right_link_second.stl" scale="0.001 0.001 0.001"/>
      </geometry>
      <material name="silver"/>
    </visual>
    <collision>
      <origin rpy="0 1.570796 0" xyz="0 0 0"/>
      <geometry>
        <mesh filename="package://kamuy2_description/meshes/front_right_link_second.stl" scale="0.001 0.001 0.001"/>
      </geometry>
    </collision>
  </link>
  <link name="back_right_link_second">
    <inertial>
      <origin rpy="0 1.570796 0" xyz="0 0 0"/>
      <mass value="0.5"/>
      <inertia ixx="0.00712" ixy="0.0" ixz="0" iyy="0.007101" iyz="0" izz="0.000185416"/>
    </inertial>
    <visual>
      <origin rpy="0 1.570796 0" xyz="0 0 0"/>
      <geometry>
        <mesh filename="package://kamuy2_description/meshes/back_right_link_second.stl" scale="0.001 0.001 0.001"/>
      </geometry>
      <material name="silver"/>
    </visual>
    <collision>
      <origin rpy="0 1.570796 0" xyz="0 0 0"/>
      <geometry>
        <mesh filename="package://kamuy2_description/meshes/back_right_link_second.stl" scale="0.001 0.001 0.001"/>
      </geometry>
    </collision>
  </link>
  <!-- first link -->
  <link name="front_right_link_first">
    <inertial>
      <origin rpy="0 0 0" xyz="0 0 0"/>
      <mass value="1.4"/>
      <inertia ixx="0.001666" ixy="0" ixz="0" iyy="0.005413" iyz="0" izz="0.0050866"/>
    </inertial>
    <visual>
      <origin rpy="0 0 0" xyz="0 0 0"/>
      <geometry>
        <mesh filename="package://kamuy2_description/meshes/front_right_link_first.stl" scale="0.001 0.001 0.001"/>
      </geometry>
      <material name="silver"/>
    </visual>
    <collision>
      <origin rpy="0 0 0" xyz="0 0 0"/>
      <geometry>
        <mesh filename="package://kamuy2_description/meshes/front_right_link_first.stl" scale="0.001 0.001 0.001"/>
      </geometry>
    </collision>
  </link>
  <link name="front_left_link_first">
    <inertial>
      <origin rpy="0 0 0" xyz="0 0 0"/>
      <mass value="1.4"/>
      <inertia ixx="0.001666" ixy="0" ixz="0" iyy="0.005413" iyz="0" izz="0.0050866"/>
    </inertial>
    <visual>
      <origin rpy="0 0 0" xyz="0 0 0"/>
      <geometry>
        <mesh filename="package://kamuy2_description/meshes/front_left_link_first.stl" scale="0.001 0.001 0.001"/>
      </geometry>
      <material name="silver"/>
    </visual>
    <collision>
      <origin rpy="0 0 0" xyz="0 0 0"/>
      <geometry>
        <mesh filename="package://kamuy2_description/meshes/front_left_link_first.stl" scale="0.001 0.001 0.001"/>
      </geometry>
    </collision>
  </link>
  <link name="back_right_link_first">
    <inertial>
      <origin rpy="0 0 0" xyz="0 0 0"/>
      <mass value="1.4"/>
      <inertia ixx="0.001666" ixy="0" ixz="0" iyy="0.005413" iyz="0" izz="0.0050866"/>
    </inertial>
    <visual>
      <origin rpy="0 0 0" xyz="0 0 0"/>
      <geometry>
        <mesh filename="package://kamuy2_description/meshes/back_right_link_first.stl" scale="0.001 0.001 0.001"/>
      </geometry>
      <material name="silver"/>
    </visual>
    <collision>
      <origin rpy="0 0 0" xyz="0 0 0"/>
      <geometry>
        <mesh filename="package://kamuy2_description/meshes/back_right_link_first.stl" scale="0.001 0.001 0.001"/>
      </geometry>
    </collision>
  </link>
  <link name="back_left_link_first">
    <inertial>
      <origin rpy="0 0 0" xyz="0.0944653660519865 0.003464242618647702 -0.03287189320851288"/>
      <mass value="1.4"/>
      <inertia ixx="0.001666" ixy="0" ixz="0" iyy="0.005413" iyz="0" izz="0.0050866"/>
    </inertial>
    <visual>
      <origin rpy="0 0 0" xyz="0 0 0"/>
      <geometry>
        <mesh filename="package://kamuy2_description/meshes/back_left_link_first.stl" scale="0.001 0.001 0.001"/>
      </geometry>
      <material name="silver"/>
    </visual>
    <collision>
      <origin rpy="0 0 0" xyz="0 0 0"/>
      <geometry>
        <mesh filename="package://kamuy2_description/meshes/back_left_link_first.stl" scale="0.001 0.001 0.001"/>
      </geometry>
    </collision>
  </link>
  <!-- foot -->
  <link name="back_left_link_foot">
    <inertial>
      <origin rpy="0 1.570796 0" xyz="0 0 0"/>
      <mass value="0.5"/>
      <inertia ixx="0.00770833" ixy="0" ixz="-0.0025" iyy="0.00895833" iyz="0" izz="0.003333"/>
    </inertial>
    <visual>
      <origin rpy="0 1.570796 0" xyz="0 0 0"/>
      <geometry>
        <mesh filename="package://kamuy2_description/meshes/back_left_link_foot.stl" scale="0.001 0.001 0.001"/>
      </geometry>
      <material name="silver"/>
    </visual>
    <collision>
      <origin rpy="0 1.570796 0" xyz="0 0 0"/>
      <geometry>
        <mesh filename="package://kamuy2_description/meshes/back_left_link_foot.stl" scale="0.001 0.001 0.001"/>
      </geometry>
    </collision>
  </link>
  <link name="front_left_link_foot">
    <inertial>
      <origin rpy="0 1.570796 0" xyz="0 0 0"/>
      <mass value="0.5"/>
      <inertia ixx="0.00770833" ixy="0" ixz="-0.0025" iyy="0.00895833" iyz="0" izz="0.003333"/>
    </inertial>
    <visual>
      <origin rpy="0 1.570796 0" xyz="0 0 0"/>
      <geometry>
        <mesh filename="package://kamuy2_description/meshes/front_left_link_foot.stl" scale="0.001 0.001 0.001"/>
      </geometry>
      <material name="silver"/>
    </visual>
    <collision>
      <origin rpy="0 1.570796 0" xyz="0 0 0"/>
      <geometry>
        <mesh filename="package://kamuy2_description/meshes/front_left_link_foot.stl" scale="0.001 0.001 0.001"/>
      </geometry>
    </collision>
  </link>
  <link name="front_right_link_foot">
    <inertial>
      <origin rpy="3.141592 1.570796 0" xyz="0 0 0"/>
      <mass value="0.5"/>
      <inertia ixx="0.00770833" ixy="0" ixz="-0.0025" iyy="0.00895833" iyz="0" izz="0.003333"/>
    </inertial>
    <visual>
      <origin rpy="3.141592 1.570796 0" xyz="0 0 0"/>
      <geometry>
        <mesh filename="package://kamuy2_description/meshes/front_right_link_foot.stl" scale="0.001 0.001 0.001"/>
      </geometry>
      <material name="silver"/>
    </visual>
    <collision>
      <origin rpy="3.141592 1.570796 0" xyz="0 0 0"/>
      <geometry>
        <mesh filename="package://kamuy2_description/meshes/front_right_link_foot.stl" scale="0.001 0.001 0.001"/>
      </geometry>
    </collision>
  </link>
  <link name="back_right_link_foot">
    <inertial>
      <origin rpy="3.141592 1.570796 0" xyz="0 0 0"/>
      <mass value="0.5"/>
      <inertia ixx="0.00770833" ixy="0" ixz="-0.0025" iyy="0.00895833" iyz="0" izz="0.003333"/>
    </inertial>
    <visual>
      <origin rpy="3.141592 1.570796 0" xyz="0 0 0"/>
      <geometry>
        <mesh filename="package://kamuy2_description/meshes/back_right_link_foot.stl" scale="0.001 0.001 0.001"/>
      </geometry>
      <material name="silver"/>
    </visual>
    <collision>
      <origin rpy="3.141592 1.570796 0" xyz="0 0 0"/>
      <geometry>
        <mesh filename="package://kamuy2_description/meshes/back_right_link_foot.stl" scale="0.001 0.001 0.001"/>
      </geometry>
    </collision>
  </link>
  <link name="front_left_foot">
</link>
  <link name="front_right_foot">
</link>
  <link name="back_left_foot">
</link>
  <link name="back_right_foot">
</link>
  <!--


<joint name="fr1" type="revolute">
  <origin xyz="0.295288 -0.072993 0.06454" rpy="0 0 0"/>
  <parent link="base_link"/>
  <child link="front_right_link_first"/>
  <axis xyz="-1.0 0.0 0.0"/>
  <limit upper="0.785398" lower="-0.785398" effort="18" velocity="0.52"/>
</joint>

<joint name="fl1" type="revolute">
  <origin xyz="0.295288 0.057189 0.06454" rpy="0 0 0"/>
  <parent link="base_link"/>
  <child link="front_left_link_first"/>
  <axis xyz="-1.0 0.0 0.0"/>
  <limit upper="0.785398" lower="-0.785398" effort="18" velocity="0.52"/>
</joint>

<joint name="br1" type="revolute">
  <origin xyz="-0.287095 -0.06509 0.031" rpy="0 0 0"/>
  <parent link="base_link"/>
  <child link="back_right_link_first"/>
  <axis xyz="-1.0 5e-06 -0.0"/>
  <limit upper="0.785398" lower="-0.785398" effort="18" velocity="0.52"/>
</joint>

<joint name="bl1" type="revolute">
  <origin xyz="-0.279337 0.057192 0.06454" rpy="0 0 0"/>
  <parent link="base_link"/>
  <child link="back_left_link_first"/>
  <axis xyz="-1.0 5e-06 -0.0"/>
  <limit upper="0.785398" lower="-0.785398" effort="18" velocity="0.52"/>
</joint>

<joint name="fl2" type="revolute">
  <origin xyz="-0.094399 0.094475 -0.033545" rpy="0 0 0"/>
  <parent link="front_left_link_first"/>
  <child link="front_left_link_second"/>
  <axis xyz="0.0 1.0 0.0"/>
  <limit upper="3.141593" lower="0.0" effort="18" velocity="0.52"/>
</joint>

<joint name="bl2" type="revolute">
  <origin xyz="0.078886 0.094475 -0.033545" rpy="0 0 0"/>
  <parent link="back_left_link_first"/>
  <child link="back_left_link_second"/>
  <axis xyz="-5e-06 -1.0 -0.0"/>
  <limit upper="0.087266" lower="-3.141593" effort="18" velocity="0.52"/>
</joint>

<joint name="fr2" type="revolute">
  <origin xyz="-0.094399 -0.078675 -0.033545" rpy="0 0 0"/>
  <parent link="front_right_link_first"/>
  <child link="front_right_link_second"/>
  <axis xyz="-0.0 1.0 -0.0"/>
  <limit upper="3.141593" lower="0.0" effort="18" velocity="0.52"/>
</joint>

<joint name="br2" type="revolute">
  <origin xyz="0.084642 -0.086575 -5e-06" rpy="0 0 0"/>
  <parent link="back_right_link_first"/>
  <child link="back_right_link_second"/>
  <axis xyz="-5e-06 -1.0 -0.0"/>
  <limit upper="0.0" lower="-3.141593" effort="18" velocity="0.52"/>
</joint>



<joint name="bl3" type="revolute">
  <origin xyz="-0.169004 0.127167 0.200451" rpy="0 0 0"/>
  <parent link="back_left_link_second"/>
  <child link="back_left_link_foot"/>
  <axis xyz="-5e-06 -1.0 -0.0"/>
  <limit upper="3.141593" lower="0.0" effort="18" velocity="0.52"/>
</joint>

<joint name="fl3" type="revolute">
  <origin xyz="-0.169005 0.130164 -0.200889" rpy="0 0 0"/>
  <parent link="front_left_link_second"/>
  <child link="front_left_link_foot"/>
  <axis xyz="-0.0 -1.0 -0.0"/>
  <limit upper="3.141593" lower="0.0" effort="18" velocity="0.52"/>
</joint>

<joint name="fr3" type="revolute">
  <origin xyz="-0.169005 -0.127168 -0.200889" rpy="0 0 0"/>
  <parent link="front_right_link_second"/>
  <child link="front_right_link_foot"/>
  <axis xyz="0.0 -1.0 0.0"/>
  <limit upper="3.141593" lower="0.0" effort="18" velocity="0.52"/>
</joint>

<joint name="br3" type="revolute">
  <origin xyz="-0.169005 -0.127165 0.202453" rpy="0 0 0"/>
  <parent link="back_right_link_second"/>
  <child link="back_right_link_foot"/>
  <axis xyz="-5e-06 -1.0 -0.0"/>
  <limit upper="3.141593" lower="0.0" effort="18" velocity="0.52"/>
</joint>

-->
  <joint name="fr1" type="revolute">
    <origin rpy="0 0 0" xyz="0.200441 -0.065042 0.030961"/>
    <parent link="base_link"/>
    <child link="front_right_link_first"/>
    <axis xyz="-1.0 0.0 0.0"/>
    <limit effort="18" lower="-0.785398" upper="0.785398" velocity="0.52"/>
  </joint>
  <joint name="fl1" type="revolute">
    <origin rpy="0 0 0" xyz="0.200441 0.065042 0.030961"/>
    <parent link="base_link"/>
    <child link="front_left_link_first"/>
    <axis xyz="-1.0 0.0 0.0"/>
    <limit effort="18" lower="-0.785398" upper="0.785398" velocity="0.52"/>
  </joint>
  <joint name="br1" type="revolute">
    <origin rpy="0 0 0" xyz="-0.200441 -0.06509 0.030961"/>
    <parent link="base_link"/>
    <child link="back_right_link_first"/>
    <axis xyz="-1.0 5e-06 -0.0"/>
    <limit effort="18" lower="-0.785398" upper="0.785398" velocity="0.52"/>
  </joint>
  <joint name="bl1" type="revolute">
    <origin rpy="0 0 0" xyz="-0.200441 0.065042 0.030961"/>
    <parent link="base_link"/>
    <child link="back_left_link_first"/>
    <axis xyz="-1.0 5e-06 -0.0"/>
    <limit effort="18" lower="-0.785398" upper="0.785398" velocity="0.52"/>
  </joint>
  <joint name="fl2" type="revolute">
    <origin rpy="0 0 0" xyz="0 0.094475 0"/>
    <parent link="front_left_link_first"/>
    <child link="front_left_link_second"/>
    <axis xyz="0.0 1.0 0.0"/>
    <limit effort="18" lower="0.0" upper="3.141593" velocity="0.52"/>
  </joint>
  <joint name="bl2" type="revolute">
    <origin rpy="0 0 0" xyz="0 0.094475 0"/>
    <parent link="back_left_link_first"/>
    <child link="back_left_link_second"/>
    <axis xyz="0.0 1.0 0.0"/>
    <limit effort="18" lower="0.0" upper="3.141593" velocity="0.52"/>
  </joint>
  <joint name="fr2" type="revolute">
    <origin rpy="0 0 0" xyz="0 -0.078675 0"/>
    <parent link="front_right_link_first"/>
    <child link="front_right_link_second"/>
    <axis xyz="-0.0 1.0 -0.0"/>
    <limit effort="18" lower="0.0" upper="3.141593" velocity="0.52"/>
  </joint>
  <joint name="br2" type="revolute">
    <origin rpy="0 0 0" xyz="0 -0.086575 0"/>
    <parent link="back_right_link_first"/>
    <child link="back_right_link_second"/>
    <axis xyz="-0.0 1.0 -0.0"/>
    <limit effort="18" lower="0.0" upper="3.141593" velocity="0.52"/>
  </joint>
  <joint name="bl3" type="revolute">
    <origin rpy="0 0 0" xyz=" 0 0 -0.200"/>
    <parent link="back_left_link_second"/>
    <child link="back_left_link_foot"/>
    <axis xyz="0 1 -0.0"/>
    <limit effort="18" lower="0.0" upper="3.141593" velocity="0.52"/>
  </joint>
  <joint name="fl3" type="revolute">
    <origin rpy="0 0 0" xyz="0 0 -0.200 "/>
    <parent link="front_left_link_second"/>
    <child link="front_left_link_foot"/>
    <axis xyz="-0.0 1.0 -0.0"/>
    <limit effort="18" lower="0.0" upper="3.141593" velocity="0.52"/>
  </joint>
  <joint name="fr3" type="revolute">
    <origin rpy="0 0 0" xyz="0 0 -0.200 "/>
    <parent link="front_right_link_second"/>
    <child link="front_right_link_foot"/>
    <axis xyz="0.0 1.0 0.0"/>
    <limit effort="18" lower="0.0" upper="3.141593" velocity="0.52"/>
  </joint>
  <joint name="br3" type="revolute">
    <origin rpy="0 0 0" xyz="0 0 -0.200 "/>
    <parent link="back_right_link_second"/>
    <child link="back_right_link_foot"/>
    <axis xyz="0 1.0 -0.0"/>
    <limit effort="18" lower="0.0" upper="3.141593" velocity="0.52"/>
  </joint>
  <joint name="fl4" type="fixed">
    <origin rpy="0 0 0" xyz="-0.05 0 -0.22"/>
    <parent link="front_left_link_foot"/>
    <child link="front_left_foot"/>
    <axis xyz="0.0 1.0 -0.0"/>
    <limit effort="18" lower="0.0" upper="3.141593" velocity="0.52"/>
  </joint>
  <joint name="fr4" type="fixed">
    <origin rpy="0 0 0" xyz="-0.05 0 -0.22 "/>
    <parent link="front_right_link_foot"/>
    <child link="front_right_foot"/>
    <axis xyz="0.0 1.0 -0.0"/>
    <limit effort="18" lower="0.0" upper="3.141593" velocity="0.52"/>
  </joint>
  <joint name="bl4" type="fixed">
    <origin rpy="0 0 0" xyz="-0.05 0 -0.22"/>
    <parent link="back_left_link_foot"/>
    <child link="back_left_foot"/>
    <axis xyz="0.0 1.0 -0.0"/>
    <limit effort="18" lower="0.0" upper="3.141593" velocity="0.52"/>
  </joint>
  <joint name="br4" type="fixed">
    <origin rpy="0 0 0" xyz="-0.05 0 -0.22"/>
    <parent link="back_right_link_foot"/>
    <child link="back_right_foot"/>
    <axis xyz="-0.0 -1.0 -0.0"/>
    <limit effort="18" lower="0.0" upper="3.141593" velocity="0.52"/>
  </joint>
</robot>

